ply
format ascii 1.0
comment : MagicaVoxel @ Ephtracy
element vertex 464
property float x
property float y
property float z
property uchar red
property uchar green
property uchar blue
end_header
-4 -3 1 255 102 0
-2 -3 1 255 102 0
1 -3 1 255 102 0
3 -3 1 255 102 0
-4 -2 1 255 102 0
-2 -2 1 255 102 0
1 -2 1 255 102 0
3 -2 1 255 102 0
-4 -1 1 255 102 0
-3 -1 1 255 102 0
-2 -1 1 255 102 0
1 -1 1 255 102 0
2 -1 1 255 102 0
3 -1 1 255 102 0
-4 0 1 255 102 0
-3 0 1 255 102 0
-2 0 1 255 102 0
1 0 1 255 102 0
2 0 1 255 102 0
3 0 1 255 102 0
-4 1 1 255 102 0
-3 1 1 255 102 0
-2 1 1 255 102 0
1 1 1 255 102 0
2 1 1 255 102 0
3 1 1 255 102 0
-3 0 2 255 102 0
2 0 2 255 102 0
-3 0 3 255 102 0
2 0 3 255 102 0
-3 -3 4 238 238 238
-2 -3 4 238 238 238
-1 -3 4 238 238 238
0 -3 4 238 238 238
1 -3 4 238 238 238
2 -3 4 238 238 238
-3 -2 4 238 238 238
-2 -2 4 238 238 238
-1 -2 4 238 238 238
0 -2 4 238 238 238
1 -2 4 238 238 238
2 -2 4 238 238 238
-4 -1 4 238 238 238
-3 -1 4 238 238 238
-2 -1 4 238 238 238
-1 -1 4 238 238 238
0 -1 4 238 238 238
1 -1 4 238 238 238
2 -1 4 238 238 238
3 -1 4 238 238 238
-4 0 4 238 238 238
-3 0 4 238 238 238
-2 0 4 238 238 238
-1 0 4 238 238 238
0 0 4 238 238 238
1 0 4 238 238 238
2 0 4 238 238 238
3 0 4 238 238 238
-4 1 4 238 238 238
-3 1 4 238 238 238
-2 1 4 238 238 238
-1 1 4 238 238 238
0 1 4 238 238 238
1 1 4 238 238 238
2 1 4 238 238 238
3 1 4 238 238 238
-4 2 4 238 238 238
-3 2 4 238 238 238
-2 2 4 238 238 238
-1 2 4 238 238 238
0 2 4 238 238 238
1 2 4 238 238 238
2 2 4 238 238 238
3 2 4 238 238 238
-4 3 4 238 238 238
-3 3 4 238 238 238
-2 3 4 238 238 238
-1 3 4 238 238 238
0 3 4 238 238 238
1 3 4 238 238 238
2 3 4 238 238 238
3 3 4 238 238 238
-3 4 4 238 238 238
-2 4 4 238 238 238
-1 4 4 238 238 238
0 4 4 238 238 238
1 4 4 238 238 238
2 4 4 238 238 238
-3 -3 5 238 238 238
-2 -3 5 238 238 238
-1 -3 5 238 238 238
0 -3 5 238 238 238
1 -3 5 238 238 238
2 -3 5 238 238 238
-3 -2 5 238 238 238
-2 -2 5 238 238 238
-1 -2 5 238 238 238
0 -2 5 238 238 238
1 -2 5 238 238 238
2 -2 5 238 238 238
-4 -1 5 238 238 238
-3 -1 5 238 238 238
-2 -1 5 238 238 238
-1 -1 5 238 238 238
0 -1 5 238 238 238
1 -1 5 238 238 238
2 -1 5 238 238 238
3 -1 5 238 238 238
-4 0 5 238 238 238
-3 0 5 238 238 238
-2 0 5 238 238 238
-1 0 5 238 238 238
0 0 5 238 238 238
1 0 5 238 238 238
2 0 5 238 238 238
3 0 5 238 238 238
-4 1 5 238 238 238
-3 1 5 238 238 238
-2 1 5 238 238 238
-1 1 5 238 238 238
0 1 5 238 238 238
1 1 5 238 238 238
2 1 5 238 238 238
3 1 5 238 238 238
-4 2 5 238 238 238
-3 2 5 238 238 238
-2 2 5 238 238 238
-1 2 5 238 238 238
0 2 5 238 238 238
1 2 5 238 238 238
2 2 5 238 238 238
3 2 5 238 238 238
-4 3 5 238 238 238
-3 3 5 238 238 238
-2 3 5 238 238 238
-1 3 5 238 238 238
0 3 5 238 238 238
1 3 5 238 238 238
2 3 5 238 238 238
3 3 5 238 238 238
-3 4 5 238 238 238
-2 4 5 238 238 238
-1 4 5 238 238 238
0 4 5 238 238 238
1 4 5 238 238 238
2 4 5 238 238 238
-3 -3 6 238 238 238
-2 -3 6 238 238 238
-1 -3 6 238 238 238
0 -3 6 238 238 238
1 -3 6 238 238 238
2 -3 6 238 238 238
-3 -2 6 238 238 238
-2 -2 6 238 238 238
-1 -2 6 238 238 238
0 -2 6 238 238 238
1 -2 6 238 238 238
2 -2 6 238 238 238
-4 -1 6 238 238 238
-3 -1 6 238 238 238
-2 -1 6 238 238 238
-1 -1 6 238 238 238
0 -1 6 238 238 238
1 -1 6 238 238 238
2 -1 6 238 238 238
3 -1 6 238 238 238
-4 0 6 238 238 238
-3 0 6 238 238 238
-2 0 6 238 238 238
-1 0 6 238 238 238
0 0 6 238 238 238
1 0 6 238 238 238
2 0 6 238 238 238
3 0 6 238 238 238
-4 1 6 238 238 238
-3 1 6 238 238 238
-2 1 6 238 238 238
-1 1 6 238 238 238
0 1 6 238 238 238
1 1 6 238 238 238
2 1 6 238 238 238
3 1 6 238 238 238
-4 2 6 238 238 238
-3 2 6 238 238 238
-2 2 6 238 238 238
-1 2 6 238 238 238
0 2 6 238 238 238
1 2 6 238 238 238
2 2 6 238 238 238
3 2 6 238 238 238
-4 3 6 238 238 238
-3 3 6 238 238 238
-2 3 6 238 238 238
-1 3 6 238 238 238
0 3 6 238 238 238
1 3 6 238 238 238
2 3 6 238 238 238
3 3 6 238 238 238
-3 4 6 238 238 238
-2 4 6 238 238 238
-1 4 6 238 238 238
0 4 6 238 238 238
1 4 6 238 238 238
2 4 6 238 238 238
-1 5 6 238 238 238
0 5 6 238 238 238
-3 -3 7 238 238 238
-2 -3 7 238 238 238
-1 -3 7 238 238 238
0 -3 7 238 238 238
1 -3 7 238 238 238
2 -3 7 238 238 238
-3 -2 7 238 238 238
-2 -2 7 238 238 238
-1 -2 7 238 238 238
0 -2 7 238 238 238
1 -2 7 238 238 238
2 -2 7 238 238 238
-3 -1 7 238 238 238
-2 -1 7 238 238 238
-1 -1 7 238 238 238
0 -1 7 238 238 238
1 -1 7 238 238 238
2 -1 7 238 238 238
-3 0 7 238 238 238
-2 0 7 238 238 238
-1 0 7 238 238 238
0 0 7 238 238 238
1 0 7 238 238 238
2 0 7 238 238 238
-3 1 7 238 238 238
-2 1 7 238 238 238
-1 1 7 238 238 238
0 1 7 238 238 238
1 1 7 238 238 238
2 1 7 238 238 238
-3 2 7 238 238 238
-2 2 7 238 238 238
-1 2 7 238 238 238
0 2 7 238 238 238
1 2 7 238 238 238
2 2 7 238 238 238
-3 3 7 238 238 238
-2 3 7 238 238 238
-1 3 7 238 238 238
0 3 7 238 238 238
1 3 7 238 238 238
2 3 7 238 238 238
-3 4 7 238 238 238
-2 4 7 238 238 238
-1 4 7 238 238 238
0 4 7 238 238 238
1 4 7 238 238 238
2 4 7 238 238 238
-2 5 7 238 238 238
-1 5 7 238 238 238
0 5 7 238 238 238
1 5 7 238 238 238
-3 -3 8 238 238 238
-2 -3 8 238 238 238
-1 -3 8 238 238 238
0 -3 8 238 238 238
1 -3 8 238 238 238
2 -3 8 238 238 238
-3 -2 8 238 238 238
-2 -2 8 238 238 238
-1 -2 8 238 238 238
0 -2 8 238 238 238
1 -2 8 238 238 238
2 -2 8 238 238 238
-3 -1 8 238 238 238
-2 -1 8 238 238 238
-1 -1 8 238 238 238
0 -1 8 238 238 238
1 -1 8 238 238 238
2 -1 8 238 238 238
-3 0 8 238 238 238
-2 0 8 238 238 238
-1 0 8 238 238 238
0 0 8 238 238 238
1 0 8 238 238 238
2 0 8 238 238 238
-3 1 8 238 238 238
-2 1 8 238 238 238
-1 1 8 238 238 238
0 1 8 238 238 238
1 1 8 238 238 238
2 1 8 238 238 238
-1 -4 9 255 51 0
0 -4 9 255 51 0
-3 -3 9 238 238 238
-2 -3 9 238 238 238
-1 -3 9 238 238 238
0 -3 9 238 238 238
1 -3 9 238 238 238
2 -3 9 238 238 238
-3 -2 9 238 238 238
-2 -2 9 238 238 238
-1 -2 9 238 238 238
0 -2 9 238 238 238
1 -2 9 238 238 238
2 -2 9 238 238 238
-3 -1 9 238 238 238
-2 -1 9 238 238 238
-1 -1 9 238 238 238
0 -1 9 238 238 238
1 -1 9 238 238 238
2 -1 9 238 238 238
-3 0 9 238 238 238
-2 0 9 238 238 238
-1 0 9 238 238 238
0 0 9 238 238 238
1 0 9 238 238 238
2 0 9 238 238 238
-3 1 9 238 238 238
-2 1 9 238 238 238
-1 1 9 238 238 238
0 1 9 238 238 238
1 1 9 238 238 238
2 1 9 238 238 238
-1 -5 10 255 102 0
0 -5 10 255 102 0
-1 -4 10 255 102 0
0 -4 10 255 102 0
-3 -3 10 238 238 238
-2 -3 10 238 238 238
-1 -3 10 238 238 238
0 -3 10 238 238 238
1 -3 10 238 238 238
2 -3 10 238 238 238
-3 -2 10 238 238 238
-2 -2 10 238 238 238
-1 -2 10 238 238 238
0 -2 10 238 238 238
1 -2 10 238 238 238
2 -2 10 238 238 238
-3 -1 10 238 238 238
-2 -1 10 238 238 238
-1 -1 10 238 238 238
0 -1 10 238 238 238
1 -1 10 238 238 238
2 -1 10 238 238 238
-3 0 10 238 238 238
-2 0 10 238 238 238
-1 0 10 238 238 238
0 0 10 238 238 238
1 0 10 238 238 238
2 0 10 238 238 238
-3 1 10 238 238 238
-2 1 10 238 238 238
-1 1 10 238 238 238
0 1 10 238 238 238
1 1 10 238 238 238
2 1 10 238 238 238
-1 -5 11 255 102 0
0 -5 11 255 102 0
-1 -4 11 255 102 0
0 -4 11 255 102 0
-3 -3 11 238 238 238
-2 -3 11 238 238 238
-1 -3 11 238 238 238
0 -3 11 238 238 238
1 -3 11 238 238 238
2 -3 11 238 238 238
-3 -2 11 238 238 238
-2 -2 11 238 238 238
-1 -2 11 238 238 238
0 -2 11 238 238 238
1 -2 11 238 238 238
2 -2 11 238 238 238
-3 -1 11 238 238 238
-2 -1 11 238 238 238
-1 -1 11 238 238 238
0 -1 11 238 238 238
1 -1 11 238 238 238
2 -1 11 238 238 238
-3 0 11 238 238 238
-2 0 11 238 238 238
-1 0 11 238 238 238
0 0 11 238 238 238
1 0 11 238 238 238
2 0 11 238 238 238
-3 1 11 238 238 238
-2 1 11 238 238 238
-1 1 11 238 238 238
0 1 11 238 238 238
1 1 11 238 238 238
2 1 11 238 238 238
-3 -3 12 238 238 238
-2 -3 12 238 238 238
-1 -3 12 238 238 238
0 -3 12 238 238 238
1 -3 12 238 238 238
2 -3 12 238 238 238
-3 -2 12 17 17 17
-2 -2 12 238 238 238
-1 -2 12 238 238 238
0 -2 12 238 238 238
1 -2 12 238 238 238
2 -2 12 17 17 17
-3 -1 12 238 238 238
-2 -1 12 238 238 238
-1 -1 12 238 238 238
0 -1 12 238 238 238
1 -1 12 238 238 238
2 -1 12 238 238 238
-3 0 12 238 238 238
-2 0 12 238 238 238
-1 0 12 238 238 238
0 0 12 238 238 238
1 0 12 238 238 238
2 0 12 238 238 238
-3 1 12 238 238 238
-2 1 12 238 238 238
-1 1 12 238 238 238
0 1 12 238 238 238
1 1 12 238 238 238
2 1 12 238 238 238
-3 -3 13 238 238 238
-2 -3 13 238 238 238
-1 -3 13 238 238 238
0 -3 13 238 238 238
1 -3 13 238 238 238
2 -3 13 238 238 238
-3 -2 13 238 238 238
-2 -2 13 238 238 238
-1 -2 13 238 238 238
0 -2 13 238 238 238
1 -2 13 238 238 238
2 -2 13 238 238 238
-3 -1 13 238 238 238
-2 -1 13 238 238 238
-1 -1 13 238 238 238
0 -1 13 238 238 238
1 -1 13 238 238 238
2 -1 13 238 238 238
-3 0 13 238 238 238
-2 0 13 238 238 238
-1 0 13 238 238 238
0 0 13 238 238 238
1 0 13 238 238 238
2 0 13 238 238 238
-3 1 13 238 238 238
-2 1 13 238 238 238
-1 1 13 238 238 238
0 1 13 238 238 238
1 1 13 238 238 238
2 1 13 238 238 238
-1 -3 14 255 0 51
0 -3 14 255 0 51
-1 -2 14 255 0 51
0 -2 14 255 0 51
-1 -1 14 255 0 51
0 -1 14 255 0 51
-1 0 14 255 0 51
0 0 14 255 0 51
-1 -3 15 255 0 51
0 -3 15 255 0 51
-1 -2 15 255 0 51
0 -2 15 255 0 51
-1 -1 15 255 0 51
0 -1 15 255 0 51
-1 0 15 255 0 51
0 0 15 255 0 51
