ply
format ascii 1.0
comment : MagicaVoxel @ Ephtracy
element vertex 376
property float x
property float y
property float z
property uchar red
property uchar green
property uchar blue
end_header
-4 0 5 152 204 204
-4 -1 5 152 204 204
-4 -2 4 152 204 204
-4 -3 9 84 84 84
-3 2 11 252 152 100
-3 2 10 252 152 100
-3 2 9 252 152 100
-3 2 8 252 152 100
-3 2 7 252 152 100
-3 2 6 152 204 204
-3 2 5 152 204 204
-3 2 4 152 204 204
-3 2 3 152 204 204
-3 2 2 152 204 204
-3 2 1 152 204 204
-3 1 11 252 152 100
-3 1 10 252 152 100
-3 1 9 252 152 100
-3 1 8 252 152 100
-3 1 7 252 152 100
-3 1 6 152 204 204
-3 1 5 152 204 204
-3 1 4 152 204 204
-3 1 3 152 204 204
-3 1 2 152 204 204
-3 1 1 152 204 204
-3 0 11 252 152 100
-3 0 10 252 152 100
-3 0 9 252 152 100
-3 0 8 252 152 100
-3 0 7 252 152 100
-3 0 6 152 204 204
-3 0 5 204 252 252
-3 0 4 152 204 204
-3 0 3 152 204 204
-3 0 2 152 204 204
-3 0 1 152 204 204
-3 -1 11 252 152 100
-3 -1 10 252 152 100
-3 -1 9 252 152 100
-3 -1 8 252 152 100
-3 -1 7 252 152 100
-3 -1 6 152 204 204
-3 -1 5 204 252 252
-3 -1 4 152 204 204
-3 -1 3 152 204 204
-3 -1 2 152 204 204
-3 -1 1 152 204 204
-3 -2 11 252 152 100
-3 -2 10 252 152 100
-3 -2 9 252 152 100
-3 -2 8 252 152 100
-3 -2 7 252 152 100
-3 -2 6 152 204 204
-3 -2 5 152 204 204
-3 -2 4 204 252 252
-3 -2 3 152 204 204
-3 -2 2 152 204 204
-3 -2 1 152 204 204
-3 -3 9 84 84 84
-3 -3 4 252 152 100
-2 2 11 252 204 152
-2 2 10 252 204 152
-2 2 9 252 204 152
-2 2 8 252 204 152
-2 2 7 252 204 152
-2 2 6 152 204 204
-2 2 5 152 204 204
-2 2 4 152 204 204
-2 2 3 152 204 204
-2 2 2 152 204 204
-2 2 1 152 204 204
-2 1 12 252 152 100
-2 1 11 204 252 252
-2 1 10 204 252 252
-2 1 9 204 252 252
-2 1 8 204 252 252
-2 1 7 204 252 252
-2 1 6 204 252 252
-2 1 5 204 252 252
-2 1 4 204 252 252
-2 1 3 204 252 252
-2 1 2 204 252 252
-2 1 1 204 252 252
-2 0 12 252 152 100
-2 0 11 204 252 252
-2 0 10 204 252 252
-2 0 9 204 252 252
-2 0 8 204 252 252
-2 0 7 204 252 252
-2 0 6 204 252 252
-2 0 5 204 252 252
-2 0 4 204 252 252
-2 0 3 204 252 252
-2 0 2 204 252 252
-2 0 1 204 252 252
-2 0 0 48 100 100
-2 -1 12 252 152 100
-2 -1 11 204 252 252
-2 -1 10 204 252 252
-2 -1 9 204 252 252
-2 -1 8 204 252 252
-2 -1 7 204 252 252
-2 -1 6 204 252 252
-2 -1 5 204 252 252
-2 -1 4 204 252 252
-2 -1 3 204 252 252
-2 -1 2 204 252 252
-2 -1 1 204 252 252
-2 -2 11 252 204 152
-2 -2 10 252 204 152
-2 -2 9 204 252 252
-2 -2 8 16 16 16
-2 -2 7 252 152 100
-2 -2 6 204 252 252
-2 -2 5 204 252 252
-2 -2 4 204 252 252
-2 -2 3 204 252 252
-2 -2 2 204 252 252
-2 -2 1 48 100 100
-2 -3 9 116 116 116
-2 -3 6 116 116 116
-2 -3 5 116 116 116
-2 -3 4 252 152 100
-2 -3 3 100 48 48
-2 -3 2 152 100 100
-2 -3 1 152 100 100
-2 -3 0 100 48 48
-1 2 11 252 204 152
-1 2 10 252 204 152
-1 2 9 252 204 152
-1 2 8 252 204 152
-1 2 7 252 204 152
-1 2 6 152 204 204
-1 2 5 152 204 204
-1 2 4 152 204 204
-1 2 3 152 204 204
-1 2 2 152 204 204
-1 2 1 152 204 204
-1 1 12 252 204 152
-1 1 11 204 252 252
-1 1 10 204 252 252
-1 1 9 204 252 252
-1 1 8 204 252 252
-1 1 7 204 252 252
-1 1 6 204 252 252
-1 1 5 204 252 252
-1 1 4 204 252 252
-1 1 3 204 252 252
-1 1 2 204 252 252
-1 1 1 204 252 252
-1 0 12 252 204 152
-1 0 11 204 252 252
-1 0 10 204 252 252
-1 0 9 204 252 252
-1 0 8 204 252 252
-1 0 7 204 252 252
-1 0 6 204 252 252
-1 0 5 204 252 252
-1 0 4 204 252 252
-1 0 3 204 252 252
-1 0 2 204 252 252
-1 0 1 204 252 252
-1 -1 12 252 204 152
-1 -1 11 204 252 252
-1 -1 10 204 252 252
-1 -1 9 204 252 252
-1 -1 8 204 252 252
-1 -1 7 204 252 252
-1 -1 6 204 252 252
-1 -1 5 204 252 252
-1 -1 4 204 252 252
-1 -1 3 204 252 252
-1 -1 2 204 252 252
-1 -1 1 204 252 252
-1 -2 11 252 204 152
-1 -2 10 252 204 152
-1 -2 9 252 204 152
-1 -2 8 252 204 152
-1 -2 7 204 252 252
-1 -2 6 204 252 252
-1 -2 5 204 252 252
-1 -2 4 204 252 252
-1 -2 3 152 204 204
-1 -2 2 152 204 204
-1 -2 1 152 204 204
-1 -3 7 116 116 116
-1 -3 6 116 116 116
-1 -3 5 116 116 116
-1 -3 4 68 68 68
0 2 11 252 204 152
0 2 10 252 204 152
0 2 9 252 204 152
0 2 8 252 204 152
0 2 7 252 204 152
0 2 6 152 204 204
0 2 5 152 204 204
0 2 4 152 204 204
0 2 3 152 204 204
0 2 2 152 204 204
0 2 1 152 204 204
0 1 12 252 204 152
0 1 11 204 252 252
0 1 10 204 252 252
0 1 9 204 252 252
0 1 8 204 252 252
0 1 7 204 252 252
0 1 6 204 252 252
0 1 5 204 252 252
0 1 4 204 252 252
0 1 3 204 252 252
0 1 2 204 252 252
0 1 1 204 252 252
0 0 12 252 204 152
0 0 11 204 252 252
0 0 10 204 252 252
0 0 9 204 252 252
0 0 8 204 252 252
0 0 7 204 252 252
0 0 6 204 252 252
0 0 5 204 252 252
0 0 4 204 252 252
0 0 3 204 252 252
0 0 2 204 252 252
0 0 1 204 252 252
0 -1 12 252 204 152
0 -1 11 204 252 252
0 -1 10 204 252 252
0 -1 9 204 252 252
0 -1 8 204 252 252
0 -1 7 204 252 252
0 -1 6 204 252 252
0 -1 5 204 252 252
0 -1 4 204 252 252
0 -1 3 204 252 252
0 -1 2 204 252 252
0 -1 1 204 252 252
0 -2 11 252 204 152
0 -2 10 252 204 152
0 -2 9 252 204 152
0 -2 8 252 204 152
0 -2 7 204 252 252
0 -2 6 204 252 252
0 -2 5 204 252 252
0 -2 4 204 252 252
0 -2 3 152 204 204
0 -2 2 204 252 252
0 -2 1 204 252 252
0 -3 7 116 116 116
0 -3 6 116 116 116
0 -3 5 116 116 116
0 -3 4 68 68 68
1 3 4 252 152 100
1 2 11 252 204 152
1 2 10 252 204 152
1 2 9 252 204 152
1 2 8 252 204 152
1 2 7 252 204 152
1 2 6 152 204 204
1 2 5 152 204 204
1 2 4 204 252 252
1 2 3 152 204 204
1 2 2 152 204 204
1 2 1 152 204 204
1 1 12 252 204 152
1 1 11 204 252 252
1 1 10 204 252 252
1 1 9 204 252 252
1 1 8 204 252 252
1 1 7 204 252 252
1 1 6 204 252 252
1 1 5 204 252 252
1 1 4 204 252 252
1 1 3 204 252 252
1 1 2 204 252 252
1 1 1 204 252 252
1 0 12 252 204 152
1 0 11 204 252 252
1 0 10 204 252 252
1 0 9 204 252 252
1 0 8 204 252 252
1 0 7 204 252 252
1 0 6 204 252 252
1 0 5 204 252 252
1 0 4 204 252 252
1 0 3 204 252 252
1 0 2 204 252 252
1 0 1 204 252 252
1 0 0 48 100 100
1 -1 12 252 204 152
1 -1 11 204 252 252
1 -1 10 204 252 252
1 -1 9 204 252 252
1 -1 8 204 252 252
1 -1 7 204 252 252
1 -1 6 204 252 252
1 -1 5 204 252 252
1 -1 4 204 252 252
1 -1 3 204 252 252
1 -1 2 204 252 252
1 -1 1 204 252 252
1 -2 11 252 252 252
1 -2 10 252 204 152
1 -2 9 204 252 252
1 -2 8 16 16 16
1 -2 7 252 204 152
1 -2 6 204 252 252
1 -2 5 204 252 252
1 -2 4 204 252 252
1 -2 3 204 252 252
1 -2 2 204 252 252
1 -2 1 204 252 252
1 -3 9 84 84 84
1 -3 6 116 116 116
1 -3 5 68 68 68
2 3 4 252 152 100
2 2 11 252 204 152
2 2 10 252 204 152
2 2 9 252 204 152
2 2 8 252 204 152
2 2 7 252 204 152
2 2 6 152 204 204
2 2 5 152 204 204
2 2 4 204 252 252
2 2 3 152 204 204
2 2 2 152 204 204
2 2 1 152 204 204
2 1 11 252 204 152
2 1 10 252 204 152
2 1 9 252 204 152
2 1 8 252 204 152
2 1 7 252 204 152
2 1 6 204 252 252
2 1 5 204 252 252
2 1 4 204 252 252
2 1 3 204 252 252
2 1 2 204 252 252
2 1 1 204 252 252
2 0 11 252 204 152
2 0 10 252 204 152
2 0 9 252 204 152
2 0 8 252 204 152
2 0 7 252 204 152
2 0 6 204 252 252
2 0 5 204 252 252
2 0 4 204 252 252
2 0 3 204 252 252
2 0 2 204 252 252
2 0 1 204 252 252
2 -1 11 252 204 152
2 -1 10 252 204 152
2 -1 9 252 204 152
2 -1 8 252 204 152
2 -1 7 252 204 152
2 -1 6 204 252 252
2 -1 5 204 252 252
2 -1 4 204 252 252
2 -1 3 204 252 252
2 -1 2 204 252 252
2 -1 1 204 252 252
2 -2 11 252 204 152
2 -2 10 252 204 152
2 -2 9 252 204 152
2 -2 8 252 204 152
2 -2 7 252 204 152
2 -2 6 204 252 252
2 -2 5 204 252 252
2 -2 4 204 252 252
2 -2 3 204 252 252
2 -2 2 204 252 252
2 -2 1 204 252 252
2 -3 9 116 116 116
3 2 4 152 204 204
3 1 5 152 204 204
3 0 5 152 204 204
3 -3 9 116 116 116
