ply
format ascii 1.0
comment : MagicaVoxel @ Ephtracy
element vertex 294
property float x
property float y
property float z
property uchar red
property uchar green
property uchar blue
end_header
1 0 6 255 255 255
-6 1 12 119 119 119
-2 2 11 119 119 119
-1 -1 10 51 102 255
-3 -1 11 119 119 119
0 2 9 51 102 255
1 0 7 119 119 119
-4 0 9 119 119 119
-5 0 5 255 153 102
2 -2 10 119 119 119
-3 0 10 119 119 119
-2 -2 8 85 85 85
1 2 8 119 119 119
2 -2 9 119 119 119
2 2 9 119 119 119
0 -1 5 170 170 170
1 -1 5 170 170 170
1 0 8 102 51 204
-2 0 5 34 34 34
-2 0 9 119 119 119
-2 0 0 68 68 68
2 1 10 119 119 119
1 0 11 119 119 119
0 -2 10 119 119 119
0 -1 3 34 34 34
-5 0 12 119 119 119
-1 -1 7 255 204 153
1 2 10 119 119 119
0 1 6 51 204 204
-1 -1 6 255 153 102
-4 0 6 119 119 119
1 3 7 119 119 119
3 0 9 119 119 119
-2 -2 10 119 119 119
-7 0 12 119 119 119
-1 2 6 119 119 119
-1 0 10 51 102 255
1 0 9 119 119 119
-4 1 8 85 85 85
-2 1 4 34 34 34
-2 1 3 119 119 119
-2 1 9 119 119 119
-2 1 7 119 119 119
1 -1 4 68 68 68
-3 -2 9 119 119 119
-3 2 8 119 119 119
-1 3 11 119 119 119
-3 1 7 119 119 119
2 2 11 119 119 119
1 2 7 119 119 119
-3 0 8 119 119 119
1 1 9 119 119 119
-1 -1 3 34 34 34
-6 0 11 119 119 119
2 2 10 119 119 119
-3 -2 8 85 85 85
0 3 7 119 119 119
3 0 8 85 85 85
-2 0 4 34 34 34
-1 2 8 51 102 255
-1 -1 5 119 119 119
1 1 10 119 119 119
-6 0 14 187 187 187
-3 -1 9 119 119 119
2 1 8 119 119 119
0 0 9 119 119 119
-1 -1 11 119 119 119
1 1 7 119 119 119
0 0 3 34 34 34
-1 1 9 51 153 255
0 2 6 119 119 119
-6 0 13 119 119 119
-1 0 11 51 102 255
0 0 10 51 102 255
-2 1 10 119 119 119
2 -1 11 119 119 119
2 0 3 255 153 102
2 0 10 119 119 119
2 0 7 119 119 119
-2 3 10 119 119 119
-2 0 2 119 119 119
1 -2 8 119 119 119
-2 -1 6 255 255 255
0 -2 8 136 136 136
-2 2 10 119 119 119
1 2 11 119 119 119
-1 -1 9 17 17 17
-1 2 10 51 102 255
0 2 11 119 119 119
1 1 4 68 68 68
2 -1 10 119 119 119
2 -2 8 119 119 119
1 1 3 119 119 119
2 -1 8 119 119 119
0 0 7 51 153 255
-3 -1 8 119 119 119
-2 0 10 51 102 255
-2 2 8 119 119 119
-6 -1 12 119 119 119
-1 3 7 119 119 119
-2 3 8 119 119 119
-3 2 7 119 119 119
1 0 3 34 34 34
1 -1 11 119 119 119
-1 1 10 51 153 255
-2 0 3 34 34 34
2 1 6 119 119 119
-3 1 11 119 119 119
1 -1 3 119 119 119
-2 3 11 119 119 119
-3 2 11 119 119 119
2 0 4 34 34 34
-1 0 6 102 51 204
0 1 5 119 119 119
1 0 5 34 34 34
-2 -1 3 119 119 119
2 2 7 119 119 119
-1 1 6 51 204 204
-1 0 3 34 34 34
-1 0 4 34 34 34
0 0 5 34 34 34
0 0 6 102 51 204
0 2 10 51 102 255
-2 3 7 119 119 119
-2 0 11 119 119 119
0 2 7 51 102 255
-2 0 7 51 153 255
2 1 11 119 119 119
-3 0 11 119 119 119
-6 0 15 221 221 221
2 -1 9 119 119 119
-2 -1 10 51 102 255
1 2 6 119 119 119
1 0 0 68 68 68
0 1 10 51 153 255
1 -1 6 255 255 255
-2 -1 7 255 153 102
-1 2 7 51 102 255
-3 1 10 119 119 119
2 0 5 34 34 34
1 1 11 119 119 119
-2 1 8 119 119 119
-2 0 8 102 51 204
1 0 1 34 34 34
1 0 2 119 119 119
-6 0 10 34 34 34
-2 0 1 34 34 34
-4 1 9 119 119 119
1 0 4 34 34 34
-1 1 7 51 153 255
-1 0 8 102 51 204
-2 2 6 119 119 119
-1 0 5 34 34 34
1 -1 7 255 204 153
-2 -1 5 119 119 119
2 0 9 119 119 119
-2 0 6 255 255 255
-3 0 7 119 119 119
-3 0 9 119 119 119
-1 -1 8 255 204 153
-4 0 5 34 34 34
2 0 11 119 119 119
-1 0 12 119 119 119
0 1 4 119 119 119
-2 -1 4 68 68 68
-1 -1 4 119 119 119
0 -1 7 255 204 153
-3 -1 10 119 119 119
0 0 11 51 102 255
-2 -1 8 17 17 17
1 -1 8 17 17 17
1 1 5 119 119 119
-1 2 9 51 102 255
-2 -1 9 17 17 17
1 2 9 119 119 119
2 -3 10 119 119 119
-2 1 5 85 85 85
0 1 11 119 119 119
-1 1 4 85 85 85
-1 1 8 51 153 255
1 -1 10 119 119 119
-1 -2 10 119 119 119
0 1 8 51 153 255
0 -1 4 170 170 170
0 0 8 102 51 204
-2 2 9 119 119 119
0 0 4 34 34 34
1 3 11 119 119 119
-1 -2 8 119 119 119
1 1 6 255 255 255
-3 2 10 119 119 119
-4 -1 6 119 119 119
-1 0 9 119 119 119
0 2 8 51 102 255
1 0 10 119 119 119
3 1 9 119 119 119
-3 2 9 119 119 119
2 0 8 119 119 119
-1 0 7 51 153 255
0 -1 11 119 119 119
-2 1 6 255 255 255
0 0 12 119 119 119
-1 2 11 119 119 119
-1 1 5 85 85 85
0 -1 8 255 204 153
-3 -3 10 85 85 85
3 1 8 85 85 85
1 -1 0 68 68 68
0 1 9 51 153 255
-1 1 11 119 119 119
0 -1 6 255 153 102
1 1 8 119 119 119
-3 1 9 119 119 119
-3 1 8 119 119 119
-2 1 11 119 119 119
-1 1 3 34 34 34
-1 -2 6 68 68 68
-3 0 5 34 34 34
2 1 9 119 119 119
-2 -1 0 68 68 68
0 -2 6 85 85 85
0 1 3 68 68 68
-2 2 7 119 119 119
-2 -1 11 119 119 119
-3 1 6 119 119 119
2 0 6 119 119 119
-3 0 6 119 119 119
-3 -1 6 119 119 119
2 -1 6 119 119 119
0 1 7 51 153 255
1 -2 11 119 119 119
3 1 6 119 119 119
-4 0 8 85 85 85
2 2 8 119 119 119
-2 -2 6 68 68 68
3 0 6 119 119 119
3 -1 6 119 119 119
1 -2 6 85 85 85
-3 -2 10 119 119 119
0 1 2 119 119 119
-2 -2 11 119 119 119
-1 1 2 85 85 85
-1 -2 11 119 119 119
-2 1 2 34 34 34
0 -2 11 119 119 119
1 -3 10 187 187 187
1 -1 2 68 68 68
0 -1 2 170 170 170
-1 -1 2 119 119 119
-2 -1 2 68 68 68
0 0 2 170 170 170
-1 0 2 119 119 119
1 1 2 68 68 68
-4 1 6 119 119 119
-6 0 12 119 119 119
1 -1 9 17 17 17
0 -1 9 17 17 17
-1 1 12 119 119 119
0 -1 10 51 102 255
1 -2 10 119 119 119
0 -3 10 136 136 136
-1 -3 10 136 136 136
0 1 12 119 119 119
1 3 8 119 119 119
0 3 8 119 119 119
-1 3 8 119 119 119
0 3 11 119 119 119
1 3 9 119 119 119
0 3 9 119 119 119
-1 3 9 119 119 119
-2 3 9 119 119 119
1 3 10 119 119 119
0 3 10 119 119 119
-1 3 10 119 119 119
2 1 7 119 119 119
-2 -3 10 85 85 85
-6 0 2 34 34 34
-6 0 1 34 34 34
-6 0 5 34 34 34
-6 0 4 34 34 34
-6 0 3 119 119 119
-6 0 0 34 34 34
-6 0 6 119 119 119
-6 0 7 34 34 34
-6 0 8 34 34 34
-6 0 9 34 34 34
2 -3 9 119 119 119
-3 -3 9 85 85 85
1 -2 9 68 68 68
0 -2 9 68 68 68
-1 -2 9 68 68 68
-2 -2 9 68 68 68
-3 0 2 85 85 85
2 0 2 85 85 85
