ply
format ascii 1.0
comment : MagicaVoxel @ Ephtracy
element vertex 334
property float x
property float y
property float z
property uchar red
property uchar green
property uchar blue
end_header
-9 0 2 252 252 252
-8 0 2 252 252 252
-7 0 2 252 252 252
-6 0 2 252 252 252
-5 0 10 48 100 252
-5 0 2 252 204 0
-4 3 8 48 100 252
-4 2 9 48 100 252
-4 2 8 48 100 252
-4 1 10 48 100 252
-4 1 9 48 100 252
-4 0 11 48 100 252
-4 0 10 48 100 252
-4 0 9 48 100 252
-4 0 8 252 152 100
-4 0 3 252 204 0
-4 0 2 252 252 252
-4 0 1 252 204 0
-4 -1 10 48 100 252
-3 2 11 48 100 252
-3 2 10 48 100 252
-3 2 9 48 100 252
-3 2 8 48 100 252
-3 2 7 48 100 252
-3 2 6 252 252 252
-3 1 12 48 100 252
-3 1 11 48 100 252
-3 1 10 48 100 252
-3 1 9 48 100 252
-3 1 8 48 100 252
-3 1 7 48 100 252
-3 1 6 252 252 252
-3 1 5 252 252 252
-3 0 12 48 100 252
-3 0 11 48 100 252
-3 0 10 48 100 252
-3 0 9 48 100 252
-3 0 8 48 100 252
-3 0 7 48 100 252
-3 0 6 252 252 252
-3 0 5 252 204 100
-3 0 4 84 84 84
-3 0 3 252 252 252
-3 0 2 48 100 204
-3 -1 11 48 100 252
-3 -1 10 48 100 252
-3 -1 9 48 100 252
-3 -1 8 48 100 252
-3 -1 6 252 252 252
-3 -2 10 48 100 252
-3 -2 9 48 100 252
-3 -2 6 252 252 252
-2 3 11 48 100 252
-2 3 10 48 100 252
-2 3 9 48 100 252
-2 3 8 48 100 252
-2 3 7 48 100 252
-2 2 12 48 100 252
-2 2 11 48 100 252
-2 2 10 48 100 252
-2 2 9 48 100 252
-2 2 8 48 100 252
-2 2 7 48 100 252
-2 2 6 252 252 252
-2 1 13 48 100 252
-2 1 12 48 100 252
-2 1 11 48 100 252
-2 1 10 48 100 252
-2 1 9 48 100 252
-2 1 8 48 100 252
-2 1 7 48 100 252
-2 1 6 48 100 252
-2 1 5 48 100 252
-2 1 4 204 204 252
-2 1 3 116 116 116
-2 1 2 204 204 252
-2 0 13 48 100 252
-2 0 12 48 100 252
-2 0 11 48 100 252
-2 0 10 48 100 252
-2 0 9 48 100 252
-2 0 8 48 100 252
-2 0 7 48 100 252
-2 0 6 48 100 252
-2 0 5 48 100 252
-2 0 4 48 100 252
-2 0 3 48 100 252
-2 0 2 48 100 252
-2 0 1 220 220 220
-2 0 0 48 100 204
-2 -1 12 48 100 252
-2 -1 11 48 100 252
-2 -1 10 48 100 252
-2 -1 9 48 100 252
-2 -1 8 16 16 16
-2 -1 7 252 152 100
-2 -1 6 48 100 252
-2 -1 5 48 100 204
-2 -1 4 204 204 252
-2 -1 3 84 84 84
-2 -1 2 204 204 252
-2 -2 11 48 100 252
-2 -2 10 48 100 252
-2 -2 6 252 252 252
-2 -3 10 48 100 252
-1 4 10 48 100 252
-1 4 9 48 100 252
-1 4 8 48 100 252
-1 3 11 48 100 252
-1 3 10 48 100 252
-1 3 9 48 100 252
-1 3 8 48 100 252
-1 3 7 48 100 252
-1 2 12 48 100 252
-1 2 11 48 100 252
-1 2 10 48 100 252
-1 2 9 48 100 252
-1 2 8 48 100 252
-1 2 7 48 100 252
-1 2 6 252 252 252
-1 1 13 48 100 252
-1 1 12 48 100 252
-1 1 11 48 100 252
-1 1 10 48 100 252
-1 1 9 48 100 252
-1 1 8 48 100 252
-1 1 7 48 100 252
-1 1 6 48 100 252
-1 1 5 48 100 252
-1 1 4 204 204 252
-1 1 3 116 116 116
-1 1 2 204 204 252
-1 0 13 48 100 252
-1 0 12 48 100 252
-1 0 11 48 100 252
-1 0 10 48 100 252
-1 0 9 48 100 252
-1 0 8 48 100 252
-1 0 7 48 100 252
-1 0 6 48 100 252
-1 0 5 48 100 252
-1 0 4 48 100 252
-1 0 3 48 100 252
-1 0 2 204 204 252
-1 -1 12 48 100 252
-1 -1 11 48 100 252
-1 -1 10 48 100 252
-1 -1 9 48 100 252
-1 -1 8 252 204 152
-1 -1 7 252 152 100
-1 -1 6 48 100 252
-1 -1 5 48 100 204
-1 -1 4 204 204 252
-1 -1 3 84 84 84
-1 -1 2 204 204 252
-1 -2 11 48 100 252
-1 -2 10 48 100 252
-1 -2 6 252 204 100
-1 -3 10 48 100 252
0 4 10 48 100 252
0 4 9 48 100 252
0 4 8 48 100 252
0 3 11 48 100 252
0 3 10 48 100 252
0 3 9 48 100 252
0 3 8 48 100 252
0 3 7 48 100 252
0 2 12 48 100 252
0 2 11 48 100 252
0 2 10 48 100 252
0 2 9 48 100 252
0 2 8 48 100 252
0 2 7 48 100 252
0 2 6 252 252 252
0 1 13 48 100 252
0 1 12 48 100 252
0 1 11 48 100 252
0 1 10 48 100 252
0 1 9 48 100 252
0 1 8 48 100 252
0 1 7 48 100 252
0 1 6 48 100 252
0 1 5 48 100 252
0 1 4 204 204 252
0 1 3 116 116 116
0 1 2 204 204 252
0 0 13 48 100 252
0 0 12 48 100 252
0 0 11 48 100 252
0 0 10 48 100 252
0 0 9 48 100 252
0 0 8 48 100 252
0 0 7 48 100 252
0 0 6 48 100 252
0 0 5 48 100 252
0 0 4 48 100 252
0 0 3 48 100 252
0 0 2 204 204 252
0 -1 12 48 100 252
0 -1 11 48 100 252
0 -1 10 48 100 252
0 -1 9 48 100 252
0 -1 8 252 204 152
0 -1 7 252 204 152
0 -1 6 48 100 252
0 -1 5 48 100 252
0 -1 4 204 204 252
0 -1 3 252 252 252
0 -1 2 252 252 252
0 -2 11 48 100 252
0 -2 10 48 100 252
0 -2 9 48 100 252
0 -2 6 252 204 100
0 -3 10 48 100 252
1 3 11 48 100 252
1 3 10 48 100 252
1 3 9 48 100 252
1 3 8 48 100 252
1 3 7 48 100 252
1 2 12 48 100 252
1 2 11 48 100 252
1 2 10 48 100 252
1 2 9 48 100 252
1 2 8 48 100 252
1 2 7 48 100 252
1 2 6 252 252 252
1 1 13 48 100 252
1 1 12 48 100 252
1 1 11 48 100 252
1 1 10 48 100 252
1 1 9 48 100 252
1 1 8 48 100 252
1 1 7 48 100 252
1 1 6 48 100 252
1 1 5 48 100 252
1 1 4 204 204 252
1 1 3 116 116 116
1 1 2 204 204 252
1 0 13 48 100 252
1 0 12 48 100 252
1 0 11 48 100 252
1 0 10 48 100 252
1 0 9 48 100 252
1 0 8 48 100 252
1 0 7 48 100 252
1 0 6 48 100 252
1 0 5 48 100 252
1 0 4 48 100 252
1 0 3 48 100 252
1 0 2 48 100 252
1 0 1 220 220 220
1 0 0 48 100 204
1 -1 12 48 100 252
1 -1 11 48 100 252
1 -1 10 48 100 252
1 -1 9 48 100 252
1 -1 8 16 16 16
1 -1 7 252 204 152
1 -1 6 48 100 252
1 -1 5 48 100 252
1 -1 4 252 252 252
1 -1 3 116 116 116
1 -1 2 204 204 252
1 -2 11 48 100 252
1 -2 10 48 100 252
1 -2 6 252 252 252
1 -3 10 48 100 252
2 2 11 48 100 252
2 2 10 48 100 252
2 2 9 48 100 252
2 2 8 48 100 252
2 2 7 48 100 252
2 2 6 252 252 252
2 1 12 48 100 252
2 1 11 48 100 252
2 1 10 48 100 252
2 1 9 48 100 252
2 1 8 48 100 252
2 1 7 48 100 252
2 1 6 252 252 252
2 1 5 252 252 252
2 0 12 48 100 252
2 0 11 48 100 252
2 0 10 48 100 252
2 0 9 48 100 252
2 0 8 48 100 252
2 0 7 48 100 252
2 0 6 252 252 252
2 0 5 252 204 100
2 0 4 136 136 136
2 0 3 252 252 252
2 0 2 48 100 252
2 -1 11 48 100 252
2 -1 10 48 100 252
2 -1 9 48 100 252
2 -1 8 48 100 252
2 -1 6 252 252 252
2 -2 10 48 100 252
2 -2 9 48 100 252
2 -2 6 252 252 252
3 3 8 48 100 252
3 2 9 48 100 252
3 2 8 48 100 252
3 2 3 252 204 0
3 2 2 252 252 252
3 2 1 252 204 0
3 1 11 48 100 252
3 1 10 48 100 252
3 1 9 48 100 252
3 1 4 252 204 0
3 1 3 252 252 252
3 1 2 252 204 0
3 1 1 252 252 252
3 1 0 252 204 0
3 0 11 48 100 252
3 0 10 48 100 252
3 0 9 48 100 252
3 0 8 252 152 100
3 0 4 252 252 252
3 0 3 252 204 0
3 0 2 252 204 0
3 0 1 252 204 0
3 0 0 252 252 252
3 -1 10 48 100 252
3 -1 4 252 204 0
3 -1 3 252 252 252
3 -1 2 252 204 0
3 -1 1 252 252 252
3 -1 0 252 204 0
3 -2 11 48 100 252
3 -2 3 252 204 0
3 -2 2 252 252 252
3 -2 1 252 204 0
4 0 10 48 100 252
