ply
format ascii 1.0
comment : MagicaVoxel @ Ephtracy
element vertex 522
property float x
property float y
property float z
property uchar red
property uchar green
property uchar blue
end_header
-2 -1 2 187 0 0
-1 1 12 255 153 51
-2 -1 13 255 153 51
1 0 13 255 153 51
2 2 6 255 153 51
1 0 0 85 85 85
2 -1 12 255 153 51
0 -2 12 255 153 51
2 3 11 255 153 51
1 -1 9 255 153 51
0 0 13 255 153 51
0 3 5 255 153 51
-4 0 7 255 153 51
-3 -2 7 255 153 51
1 -1 13 255 153 51
-4 0 10 255 153 51
-4 -1 10 255 153 51
-4 2 9 255 153 51
-2 3 10 255 153 51
1 1 11 255 153 51
-2 1 13 255 153 51
0 -1 11 255 153 51
-4 1 10 255 153 51
-3 1 3 187 0 0
1 -3 11 255 153 51
-3 2 7 255 153 51
-1 -1 7 255 153 102
-1 0 11 255 153 51
-2 0 11 255 153 51
0 4 10 255 153 51
0 -1 9 255 153 51
-4 0 9 255 153 51
3 0 9 255 153 51
-1 2 12 255 153 51
3 -2 10 255 153 51
2 0 12 255 153 51
-3 0 3 187 0 0
-2 0 13 255 153 51
3 -1 10 255 153 51
-4 2 8 255 153 51
-3 -1 12 255 153 51
2 -2 7 255 153 51
3 4 6 255 153 51
-1 4 8 255 153 51
-3 0 11 255 153 51
2 2 1 187 0 0
1 4 9 255 153 51
0 0 12 255 153 51
-2 3 11 255 153 51
1 2 10 255 153 51
0 -1 12 255 153 51
1 0 12 255 153 51
-1 1 11 255 153 51
-1 2 10 255 153 51
-2 -1 8 17 17 17
-2 -1 12 255 153 51
-3 1 7 255 153 51
-1 1 13 255 153 51
-1 -1 6 221 0 0
-2 0 12 255 153 51
-2 0 0 85 85 85
1 -1 1 187 0 0
0 2 12 255 153 51
-3 0 12 255 153 51
1 2 11 255 153 51
-3 -2 11 255 153 51
-3 -1 2 187 0 0
-2 -2 11 255 153 51
-1 -2 11 255 153 51
3 -3 7 255 153 51
-1 3 2 255 153 51
1 4 8 255 153 51
-3 0 5 255 255 255
2 2 11 255 153 51
0 -1 8 255 204 153
0 2 11 255 153 51
1 0 4 255 255 255
2 -3 10 255 153 51
0 3 10 255 153 51
2 -3 9 255 153 51
2 1 11 255 153 51
2 2 8 255 153 51
-1 -1 2 221 0 0
-1 0 12 255 153 51
-3 2 10 255 153 51
-4 2 10 255 153 51
-1 -1 9 255 153 51
0 1 11 255 153 51
-1 0 2 255 255 255
0 -2 11 255 153 51
2 0 5 255 255 255
3 2 9 255 153 51
-3 3 11 255 153 51
1 2 6 255 153 51
1 -2 11 255 153 51
-3 -1 8 255 153 51
-4 -3 7 255 153 51
1 3 10 255 153 51
0 1 12 255 153 51
-2 1 10 255 153 51
-3 2 8 255 153 51
-2 0 5 255 255 255
1 0 3 255 204 153
4 1 5 255 153 51
-1 0 4 255 255 255
-2 0 3 255 204 153
2 -2 11 255 153 51
2 2 7 255 153 51
-1 3 6 255 153 51
-2 4 10 255 153 51
0 0 4 255 255 255
3 2 8 255 153 51
-2 0 4 255 255 255
-5 1 5 255 153 51
1 0 5 255 255 255
3 0 4 255 153 102
2 -1 11 255 153 51
-1 -1 8 255 204 153
1 -2 6 255 153 51
-2 -2 6 255 153 51
0 0 5 255 255 255
-1 4 10 255 153 51
-1 3 5 255 153 51
0 4 8 255 153 51
-4 -1 1 187 0 0
1 -2 1 187 0 0
2 2 10 255 153 51
-2 2 6 255 153 51
-2 2 12 255 153 51
3 1 10 255 153 51
2 1 2 187 0 0
2 0 2 187 0 0
2 -1 2 187 0 0
-3 -3 10 255 153 51
-3 2 3 187 0 0
1 2 3 255 255 255
-2 -1 7 255 153 102
0 2 10 255 153 51
0 -2 10 255 153 51
-3 1 2 187 0 0
-3 0 2 187 0 0
-3 1 11 255 153 51
2 -1 1 187 0 0
0 2 3 255 255 255
2 0 3 187 0 0
2 0 11 255 153 51
-2 0 1 187 0 0
1 4 10 255 153 51
3 0 6 255 153 51
1 -1 8 17 17 17
-1 2 11 255 153 51
-3 -2 8 255 153 51
-1 0 5 255 255 255
1 -1 7 255 204 153
1 4 5 255 153 51
2 1 12 255 153 51
-2 4 9 255 153 51
-3 0 7 255 153 51
0 0 2 255 255 255
-2 2 10 255 153 51
-1 -1 13 255 153 51
-3 2 12 255 153 51
3 0 11 255 153 51
1 -1 2 221 0 0
1 2 12 255 153 51
2 2 12 255 153 51
0 -1 7 255 204 153
-1 -3 11 255 153 51
2 -2 1 187 0 0
-2 1 12 255 153 51
1 1 12 255 153 51
-2 3 8 255 153 51
3 -3 8 255 153 51
0 -1 2 221 0 0
0 1 13 255 153 51
-1 -1 12 255 153 51
1 3 8 255 153 51
-4 -3 8 255 153 51
-2 -2 12 255 153 51
-2 4 2 255 153 51
-3 -3 9 255 153 51
2 4 10 255 153 51
1 4 2 255 153 51
3 2 10 255 153 51
-3 -2 10 255 153 51
0 3 6 255 153 51
-2 -2 1 187 0 0
-4 -1 11 255 153 51
-4 4 6 255 153 51
5 3 3 255 153 51
2 -1 7 255 153 51
2 0 7 136 136 136
0 1 5 255 255 255
1 3 11 255 153 51
-1 -2 10 255 153 51
3 -2 9 255 153 51
-4 -2 9 255 153 51
-4 -2 10 255 153 51
-3 2 1 187 0 0
-1 3 11 255 153 51
3 -1 11 255 153 51
-4 1 11 255 153 51
-4 0 11 255 153 51
-1 0 13 255 153 51
-1 3 7 255 153 51
-3 1 12 255 153 51
1 -1 12 255 153 51
-2 4 8 255 153 51
-1 2 6 255 153 51
-1 3 10 255 153 51
0 -2 2 221 0 0
-3 5 3 255 153 51
0 2 6 255 153 51
3 0 1 187 0 0
-4 0 8 255 153 51
0 3 7 255 153 51
2 -2 9 255 153 51
3 1 11 255 153 51
-2 1 11 255 153 51
0 0 11 255 153 51
2 -2 8 255 153 51
-4 0 6 255 153 51
2 5 3 255 153 51
-4 1 5 255 153 51
-3 -1 11 255 153 51
2 1 3 187 0 0
3 1 5 255 153 51
1 1 13 255 153 51
0 3 11 255 153 51
-3 -1 7 255 153 51
-1 -2 12 255 153 51
-3 -2 9 255 153 51
3 -3 9 255 153 51
-1 1 5 255 255 255
1 1 2 187 0 0
0 -3 11 255 153 51
2 -1 8 255 153 51
-1 3 3 255 153 51
-1 1 2 187 0 0
-1 1 4 255 255 255
-2 1 5 255 255 255
1 -1 3 187 0 0
1 1 5 255 255 255
1 0 11 255 153 51
0 0 3 255 204 255
1 4 4 255 153 51
-1 -1 11 255 153 51
-2 6 5 255 153 51
0 1 4 255 255 255
-2 0 6 255 204 255
1 1 3 238 238 238
-1 4 9 255 153 51
3 0 10 255 153 51
0 4 9 255 153 51
-2 2 3 255 255 255
5 2 4 255 153 51
1 -2 12 255 153 51
0 1 2 187 0 0
-1 0 3 255 204 255
-2 -3 11 255 153 51
1 -1 11 255 153 51
-1 3 4 255 153 51
-1 2 3 255 255 255
1 0 1 187 0 0
-4 -3 9 255 153 51
0 3 8 255 153 51
-1 3 8 255 153 51
-3 1 10 255 153 51
-1 1 3 255 255 255
-2 1 3 238 238 238
1 4 6 255 153 51
-2 -1 11 255 153 51
-2 1 2 187 0 0
1 5 4 255 153 51
-4 1 1 187 0 0
0 -1 3 221 0 0
0 -1 6 255 51 204
-2 -1 3 187 0 0
1 1 4 255 255 255
-2 1 4 255 255 255
-4 0 4 255 153 102
0 -1 13 255 153 51
2 2 3 187 0 0
-1 -1 3 187 0 0
0 1 3 255 255 255
-2 5 4 255 153 51
1 0 2 255 255 255
-2 0 2 187 0 0
1 -1 6 255 153 51
-2 -1 6 255 153 51
1 0 6 255 153 51
0 0 6 255 153 51
-1 0 6 255 153 51
1 1 6 255 153 51
0 1 6 255 153 51
-1 1 6 255 153 51
-2 1 6 255 153 51
1 0 7 255 153 51
0 0 7 255 153 51
-1 0 7 255 153 51
-2 0 7 255 153 51
2 1 7 255 153 51
1 1 7 255 153 51
0 1 7 255 153 51
-1 1 7 255 153 51
-2 1 7 255 153 51
1 2 7 255 153 51
0 2 7 255 153 51
-1 2 7 255 153 51
-2 2 7 255 153 51
2 0 8 255 153 51
1 0 8 255 153 51
0 0 8 255 153 51
-1 0 8 255 153 51
-2 0 8 255 153 51
-3 0 8 255 153 51
2 1 8 255 153 51
1 1 8 255 153 51
0 1 8 255 153 51
-1 1 8 255 153 51
-2 1 8 255 153 51
-3 1 8 255 153 51
1 2 8 255 153 51
0 2 8 255 153 51
-1 2 8 255 153 51
-2 2 8 255 153 51
2 -1 9 255 153 51
-2 -1 9 255 153 51
-3 -1 9 255 153 51
2 0 9 255 153 51
1 0 9 255 153 51
0 0 9 255 153 51
-1 0 9 255 153 51
-2 0 9 255 153 51
-3 0 9 255 153 51
2 1 9 255 153 51
1 1 9 255 153 51
0 1 9 255 153 51
-1 1 9 255 153 51
-2 1 9 255 153 51
-3 1 9 255 153 51
2 2 9 255 153 51
1 2 9 255 153 51
0 2 9 255 153 51
-1 2 9 255 153 51
-2 2 9 255 153 51
-3 2 9 255 153 51
1 3 9 255 153 51
0 3 9 255 153 51
-1 3 9 255 153 51
-2 3 9 255 153 51
2 -2 10 255 153 51
-3 2 11 255 153 51
-2 2 11 255 153 51
2 -1 10 255 153 51
1 -1 10 255 153 51
0 -1 10 255 153 51
-1 -1 10 255 153 51
-2 -1 10 255 153 51
-3 -1 10 255 153 51
2 0 10 255 153 51
1 0 10 255 153 51
0 0 10 255 153 51
-1 0 10 255 153 51
-2 0 10 255 153 51
-3 0 10 255 153 51
2 1 10 255 153 51
1 1 10 255 153 51
0 1 10 255 153 51
-1 1 10 255 153 51
1 2 4 255 153 51
1 2 5 255 153 51
-2 2 4 255 153 51
-2 2 5 255 153 51
2 1 4 255 153 51
2 1 5 255 153 51
-3 1 4 255 153 51
-3 1 5 255 153 51
4 2 2 255 153 51
3 2 3 255 153 51
3 2 4 255 153 51
3 2 5 255 153 51
3 2 6 255 153 51
3 2 7 255 153 51
-1 -2 9 255 153 51
-4 2 3 255 153 51
-4 2 4 255 153 51
-4 2 5 255 153 51
-4 2 6 255 153 51
-4 2 7 255 153 51
-5 1 3 255 153 51
4 1 3 255 153 51
-3 -2 1 187 0 0
2 3 3 255 153 51
2 3 4 255 153 51
2 3 5 255 153 51
1 6 5 255 153 51
3 0 8 255 153 51
3 0 7 255 153 51
-2 -2 2 187 0 0
-3 3 3 255 153 51
-3 3 4 255 153 51
-3 3 5 255 153 51
1 4 7 255 153 51
-3 4 10 255 153 51
-6 3 3 255 153 51
-1 4 3 255 153 51
0 4 3 255 153 51
1 3 2 255 153 51
1 3 3 255 153 51
1 3 4 255 153 51
1 3 5 255 153 51
1 3 6 255 153 51
1 3 7 255 153 51
-2 3 2 255 153 51
-2 3 3 255 153 51
-2 3 4 255 153 51
-2 3 5 255 153 51
-2 3 6 255 153 51
-2 3 7 255 153 51
0 3 2 255 153 51
0 3 3 255 153 51
0 3 4 255 153 51
-1 2 2 187 0 0
-2 2 2 187 0 0
-5 2 2 255 153 51
0 -2 9 255 153 51
1 2 2 187 0 0
0 2 2 187 0 0
0 -2 1 221 0 0
-2 -1 1 187 0 0
-3 -1 1 187 0 0
-1 -2 1 187 0 0
-1 -1 1 187 0 0
0 -1 1 187 0 0
-3 3 6 255 153 51
-3 3 7 255 153 51
-3 3 8 255 153 51
-3 3 9 255 153 51
-3 3 10 255 153 51
2 3 6 255 153 51
2 3 7 255 153 51
2 3 8 255 153 51
2 3 9 255 153 51
2 3 10 255 153 51
-4 3 5 255 153 51
-2 4 7 255 153 51
-2 4 6 255 153 51
-2 4 5 255 153 51
-2 4 4 255 153 51
-1 -2 2 187 0 0
3 3 5 255 153 51
-6 2 4 255 153 51
1 -1 4 255 255 255
0 -1 4 255 255 255
1 -1 5 255 255 255
0 -1 5 221 0 0
-1 -1 4 221 0 0
-2 -1 4 255 255 255
-1 -1 5 255 255 255
-2 -1 5 255 255 255
-3 0 1 187 0 0
-2 1 1 187 0 0
-3 1 1 187 0 0
-2 2 1 187 0 0
2 3 2 255 153 51
0 1 1 187 0 0
0 2 1 187 0 0
-1 1 1 187 0 0
-1 2 1 187 0 0
0 0 1 187 0 0
-1 0 1 187 0 0
2 1 1 187 0 0
1 1 1 187 0 0
-3 3 2 255 153 51
1 2 1 187 0 0
2 0 1 187 0 0
-4 0 1 187 0 0
3 1 1 187 0 0
1 -2 2 187 0 0
3 -1 1 187 0 0
1 -2 10 68 68 68
-2 -2 10 68 68 68
-7 0 0 255 153 0
-7 0 1 255 204 102
-7 0 2 255 204 102
-7 0 3 255 204 102
-7 0 4 255 204 102
-7 0 5 255 204 102
-7 0 6 255 204 102
-7 0 7 255 153 0
-7 2 9 255 204 102
-7 0 9 255 204 102
-7 0 10 255 204 102
-8 0 8 255 204 102
-6 0 13 255 204 102
-7 -2 9 255 204 102
-9 0 12 255 204 102
-7 0 11 255 204 102
-5 0 10 255 204 102
-7 -2 11 255 204 102
-7 2 11 255 204 102
-7 -2 10 255 204 102
-7 0 12 255 204 102
-5 0 9 255 204 102
-7 2 10 255 204 102
-5 0 12 255 204 102
-5 0 11 255 204 102
-7 2 12 255 204 102
-8 0 13 255 204 102
-9 0 11 255 204 102
-9 0 10 255 204 102
-9 0 9 255 204 102
-6 0 8 255 204 102
-7 -2 12 255 204 102
-7 1 8 255 204 102
-7 0 8 255 204 102
-7 -1 8 255 204 102
-7 1 13 255 204 102
-7 -1 13 255 204 102
-7 0 13 255 153 0
-7 0 14 255 153 0
