ply
format ascii 1.0
comment : MagicaVoxel @ Ephtracy
element vertex 399
property float x
property float y
property float z
property uchar red
property uchar green
property uchar blue
end_header
-2 1 5 255 204 51
-1 0 12 255 204 51
-2 1 11 255 204 51
-1 -2 10 102 153 102
-3 -2 11 255 204 51
-3 -1 6 255 153 102
1 -1 7 102 51 204
-4 -1 9 255 204 51
-5 -1 3 255 153 102
1 -2 9 255 153 102
-3 -1 10 102 51 204
3 -1 10 255 204 51
-6 3 6 204 153 102
-3 1 5 255 204 51
2 1 9 255 204 51
0 -2 5 238 238 238
1 -2 5 51 153 102
1 -1 8 102 51 204
-2 -1 5 34 34 34
-2 -1 9 102 51 204
-2 -1 0 102 204 153
2 0 10 51 51 102
3 3 4 255 204 51
-3 1 4 255 204 51
0 -2 3 238 238 238
-3 1 7 255 204 51
-1 -2 7 255 153 102
1 1 10 255 204 51
0 0 6 255 204 51
-1 -2 6 51 153 102
0 -2 9 255 204 153
0 0 7 102 51 204
3 -1 9 255 204 51
-2 -3 10 255 204 51
-6 4 6 153 102 51
0 -3 10 255 204 51
-1 -1 10 102 51 204
1 -1 9 102 51 204
3 -2 10 255 204 51
-2 0 4 153 102 51
-2 0 3 238 238 238
-6 3 5 153 102 51
-2 0 7 102 51 204
1 -2 4 153 102 51
-4 -2 10 255 204 51
-2 -1 12 255 204 51
-4 -2 9 255 204 51
1 -2 12 255 204 51
2 1 7 255 204 51
1 1 7 255 204 51
2 1 5 255 204 51
-1 1 12 255 204 51
-1 -2 3 238 238 238
-6 4 5 204 153 102
2 1 6 255 204 51
3 -1 11 255 204 51
-3 0 7 102 51 204
3 -1 8 255 153 102
-2 -1 4 153 102 51
-1 1 8 255 204 51
-1 -2 5 221 221 221
1 0 10 102 51 204
-7 3 5 204 153 102
-7 4 5 153 102 51
2 0 8 102 51 204
0 -1 9 102 51 204
-2 1 12 255 204 51
1 0 7 102 51 204
0 -1 3 238 238 238
-1 0 9 102 51 204
1 -2 10 102 153 102
-1 -1 13 255 204 51
-2 3 5 204 153 102
0 -1 10 102 51 204
-2 0 10 102 51 204
2 -2 11 255 204 51
5 -1 6 255 153 102
2 -1 10 51 51 102
2 -1 7 255 204 51
-4 -1 8 255 153 102
-2 -1 2 255 153 102
2 1 8 255 204 51
-2 -2 6 51 153 102
-4 0 8 255 204 51
-2 1 10 255 204 51
1 1 11 255 204 51
-1 -2 9 255 153 102
-1 1 10 255 204 51
0 1 11 255 204 51
1 0 4 153 102 51
2 1 4 255 204 51
-4 -1 11 255 204 51
1 0 3 238 238 238
1 1 6 255 204 51
0 -1 7 102 51 204
-3 -2 8 255 204 51
-2 -1 10 102 51 204
-2 1 8 255 204 51
0 0 12 255 204 51
2 0 7 102 51 204
-3 1 8 255 204 51
-2 0 12 255 204 51
1 -1 3 238 238 238
1 -2 11 255 204 51
-1 0 10 102 51 204
-2 -1 3 238 238 238
-4 0 7 255 204 51
-3 1 6 255 204 51
1 -2 3 238 238 238
3 0 9 255 204 51
0 1 12 255 204 51
4 -1 6 102 204 153
-1 -1 6 102 51 204
0 0 5 255 204 51
1 -1 5 51 153 102
-2 -2 3 221 221 221
1 -1 12 255 204 51
-1 0 6 255 204 51
-1 -1 3 238 238 238
-1 -1 4 34 34 34
0 -1 5 34 34 34
1 1 12 255 204 51
0 1 10 255 204 51
0 1 7 255 204 51
-3 -2 6 255 204 51
1 0 12 255 204 51
-2 -1 7 102 51 204
-2 1 6 255 204 51
-4 3 4 255 204 51
3 0 10 255 204 51
2 -2 9 102 51 204
-2 -2 10 102 153 102
0 -2 10 102 153 102
1 -1 0 102 204 153
0 0 10 102 51 204
1 1 5 255 204 51
-2 -2 7 255 153 102
-1 1 7 255 204 51
-3 -2 7 255 204 51
3 -1 6 255 153 102
1 0 11 255 204 51
-2 0 8 102 51 204
0 3 5 34 34 34
1 -1 1 255 153 102
1 -1 2 255 153 102
3 0 6 255 204 51
-2 -1 1 255 153 102
-4 0 9 255 204 51
1 -1 4 153 102 51
-1 0 7 102 51 204
-1 -1 8 102 51 204
1 -3 10 255 204 51
-1 -1 5 34 34 34
1 -2 7 255 204 153
-2 -2 5 51 153 102
2 -1 9 102 51 204
-2 -1 6 102 51 204
-3 -1 7 255 204 51
-3 -1 9 102 51 204
-1 -2 8 255 204 153
-4 -1 4 102 204 153
4 -1 8 255 153 102
-1 -1 12 255 204 51
0 0 4 153 102 51
-2 -2 4 153 102 51
-1 -2 4 153 102 51
0 -2 7 255 204 153
2 -1 6 255 153 102
0 -1 11 255 204 51
-2 -2 8 17 17 17
1 -2 8 17 17 17
1 0 5 51 153 102
-1 1 9 255 204 51
-2 -2 9 255 153 102
1 1 9 255 204 51
-3 -1 12 255 204 51
-2 0 5 51 153 102
0 0 11 255 204 51
-1 0 4 153 102 51
-1 0 8 102 51 204
2 0 6 255 204 51
-1 -3 10 255 204 51
0 0 8 102 51 204
0 -2 4 204 153 102
0 -1 8 102 51 204
-2 1 9 255 204 51
0 -1 4 34 34 34
3 -2 9 255 204 51
3 0 8 255 204 51
1 0 6 102 51 204
-3 1 10 255 204 51
3 0 7 255 204 51
-1 -1 9 102 51 204
0 1 8 255 204 51
1 -1 10 102 51 204
-2 -2 12 255 204 51
-3 1 9 255 204 51
2 -1 8 255 153 102
-1 -1 7 102 51 204
0 -2 11 255 204 51
-2 0 6 102 51 204
0 -1 12 255 204 51
-1 1 11 255 204 51
-1 0 5 255 204 51
0 -2 8 255 204 153
2 -1 12 255 204 51
-7 4 6 204 153 102
0 -1 13 255 204 51
0 0 9 102 51 204
-3 0 6 255 204 51
0 -2 6 102 204 153
1 0 8 102 51 204
-7 3 6 153 102 51
-3 -3 7 255 204 51
-1 3 5 68 68 68
-1 0 3 238 238 238
2 -3 9 255 204 51
-3 -1 5 255 153 102
2 0 9 102 51 204
1 -1 13 255 204 51
1 3 8 255 204 51
0 0 3 238 238 238
-2 1 7 255 204 51
-2 -2 11 255 204 51
-1 0 11 255 204 51
-3 -2 10 255 204 51
0 1 9 255 204 51
-2 0 11 255 204 51
2 -3 7 255 204 51
1 0 9 102 51 204
0 -1 6 102 51 204
-3 -3 9 255 204 51
2 -2 7 255 204 51
2 0 11 255 204 51
1 -1 6 102 51 204
2 -3 8 255 204 51
2 -2 8 255 204 51
1 -2 6 51 153 102
-1 -2 11 255 204 51
2 1 10 255 204 51
2 -2 10 255 204 51
-3 -1 8 255 153 102
-3 -2 9 102 51 204
-2 -1 13 255 204 51
-3 0 10 102 51 204
-3 0 11 255 204 51
-3 -1 11 255 204 51
-5 -1 8 255 153 102
-3 0 8 102 51 204
-2 -1 8 102 51 204
-2 -1 11 255 204 51
-4 -1 10 255 204 51
-1 3 6 34 34 34
0 -2 12 255 204 51
-1 -1 11 255 204 51
-4 0 6 255 204 51
-4 0 10 255 204 51
-1 -2 12 255 204 51
1 -1 11 255 204 51
-2 0 9 102 51 204
-3 0 9 102 51 204
1 1 8 255 204 51
2 -1 11 255 204 51
-4 1 5 255 204 51
3 1 5 255 204 51
-1 0 13 255 204 51
-2 0 13 255 204 51
1 0 13 255 204 51
0 0 13 255 204 51
0 1 5 255 204 51
-1 1 5 255 204 51
0 1 6 255 204 51
-1 1 6 255 204 51
1 2 5 255 204 51
0 2 5 255 204 51
-1 2 5 255 204 51
-2 2 5 255 204 51
1 2 6 255 204 51
0 2 6 255 204 51
-1 2 6 255 204 51
-2 2 6 255 204 51
1 2 7 255 204 51
0 2 7 255 204 51
-1 2 7 255 204 51
-2 2 7 255 204 51
1 2 8 255 204 51
0 2 8 255 204 51
-1 2 8 255 204 51
-2 2 8 255 204 51
1 2 9 255 204 51
0 2 9 255 204 51
-1 2 9 255 204 51
-2 2 9 255 204 51
-2 3 8 255 204 51
2 0 12 255 204 51
3 0 11 255 204 51
2 1 11 255 204 51
3 1 6 255 204 51
3 1 7 255 204 51
3 1 8 255 204 51
3 1 9 255 204 51
3 1 10 255 204 51
2 2 5 255 204 51
-3 3 7 255 204 51
2 3 7 255 204 51
2 2 8 255 204 51
4 2 4 255 204 51
3 2 4 255 204 51
2 2 4 255 204 51
3 2 3 255 204 51
3 2 5 255 204 51
-3 2 4 255 204 51
-4 2 4 255 204 51
-5 2 4 255 204 51
-4 2 5 255 204 51
-4 2 3 255 204 51
-3 2 5 255 204 51
1 4 7 255 204 51
-2 4 7 255 204 51
-3 2 8 255 204 51
2 -2 6 255 204 51
-4 1 6 255 204 51
-4 1 7 255 204 51
-4 1 8 255 204 51
-4 1 9 255 204 51
-4 1 10 255 204 51
-3 1 11 255 204 51
-3 0 12 255 204 51
-4 0 11 255 204 51
1 2 11 255 204 51
0 2 11 255 204 51
-1 2 11 255 204 51
-2 2 11 255 204 51
2 2 10 255 204 51
-1 2 10 255 204 51
2 2 9 255 204 51
-3 2 10 255 204 51
-3 2 9 255 204 51
-2 2 10 255 204 51
1 2 10 255 204 51
0 2 10 255 204 51
1 3 5 204 153 102
0 3 6 68 68 68
4 -2 2 187 187 187
4 -2 0 153 102 51
6 -1 2 153 102 51
6 -1 3 204 153 102
6 -1 4 204 153 102
6 -1 5 153 102 51
6 -1 6 153 102 51
6 -1 7 153 102 51
6 -1 8 153 102 51
6 -1 9 204 153 102
6 -1 10 204 153 102
6 -1 11 153 102 51
4 -2 3 187 187 187
4 -2 11 221 221 221
4 -2 13 153 102 51
4 -2 4 187 187 187
4 -2 10 221 221 221
4 -2 5 187 187 187
4 -2 6 187 187 187
4 -2 7 221 221 221
4 -2 8 221 221 221
4 -2 9 221 221 221
5 -2 12 153 102 51
5 -2 1 153 102 51
4 -2 12 170 170 170
4 -2 1 170 170 170
-3 3 5 204 153 102
2 3 5 204 153 102
-3 3 6 153 102 51
-2 3 6 153 102 51
1 3 6 153 102 51
2 3 6 153 102 51
2 4 5 153 102 51
1 4 5 153 102 51
0 4 5 68 68 68
-1 4 5 34 34 34
-2 4 5 153 102 51
-3 4 5 153 102 51
2 4 6 204 153 102
1 4 6 204 153 102
0 4 6 34 34 34
-1 4 6 68 68 68
-2 4 6 204 153 102
-3 4 6 204 153 102
-4 3 6 153 102 51
-4 4 6 204 153 102
-4 3 5 204 153 102
-4 4 5 153 102 51
-5 3 5 204 153 102
-5 4 5 153 102 51
-5 3 6 153 102 51
-5 4 6 204 153 102
-3 -3 8 255 204 51
-2 -3 9 255 204 51
1 -3 9 255 204 51
-1 -3 9 255 204 51
